Workbook

Sheet Resumen
B1: Movilización del taladro GRS 110 en La Cira Infantas: Work Order frente a modelo tercerizado
B2: Evaluación para decidir si se mantiene el Work Order o se contrata directamente al transportador. No es un proceso de adjudicación.
B5: 1. QUÉ SE EVALUÓ
B6: Dos formas de pagar las movilizaciones del taladro GRS 110. Work Order (modelo directo): el contratista del taladro cobra una suma global por movilización según la distancia, con tarifa tope, y no se pagan horas de taladro. Modelo tercerizado: SierraCol contrata al transportador y paga además el taladro por cada hora que dura la movilización y un coordinador de transporte (Truck Manager).
B7: Ofertas evaluadas: Petro Star tarifa normal, Petro Star Lump Sum (precio cerrado) y Ecotransur. MTI y Transtecol quedan por fuera porque sus tarifas no se actualizaron a julio de 2026.
B9: 2. ARCHIVO DE TRABAJO Y FUENTES
B10: Este libro es el archivo de trabajo del ejercicio. Las hojas Simulador, Real 2024 y Real 2025 calculan con fórmulas; las demás documentan y verifican.
B11: Fuente | C11: Qué se tomó de ella
B12: Tarifas con evaluaciones minimas.xlsx | C12: Tarifas de las tres ofertas (filas amarillas 'Costo Suma Global'), TRM, tarifa del taladro, horas por rango y Truck Manager.
B13: Cotización 1255 de Petro Star (17-jul-2026) | C13: Tiempos por rango, descuento desde la 6ª, cargo fijo de 0 a 5 movilizaciones, tarifas por hora de equipos y señalizadores, condición 7 sobre demoras.
B14: Ajuste de tarifas de Ecotransur (27-jul-2026) | C14: Nómina y stand-by de 0 a 4 movilizaciones, sin cargo fijo desde la 5ª, solo equipos desde la 6ª.
B15: Movilizaciones 2024 y 2025 (GRS 110) | C15: Frecuencia mensual, mezcla por distancia y horas reales de cada movilización.
B16: Evaluación SierraCol v5, hoja NPT Social 2025 | C16: Bloqueos registrados en OpenWells durante la fase de movilización (01MIRU).
B17: Premisas de SierraCol | C17: Tarifas WO y sus 12 señalizadoras, campaña de 35 pozos, 5 a 6 movilizaciones por mes, TRM 3.700, costo de pozo 600 k.
B19: 3. CONSIDERACIONES DEL EJERCICIO
B20: 1. Campaña proyectada: 35 pozos, 15 en la misma localización y 20 entre 0,1 y 5 km. Frecuencia esperada de 5 a 6 movilizaciones por mes; se analiza de 4 a 8.
B21: 2. Las movilizaciones se asignan a meses enteros. El número de la movilización dentro del mes define si hay cargo fijo (hasta la 5ª en Petro Star, hasta la 4ª en Ecotransur) y si hay descuento (desde la 6ª).
B22: 3. Work Order: tarifa del Excel por rango más 8 señalizadoras que faltan (4 por turno a 375.000 COP). Esa tarifa es el tope: si la movilización tarda más, el WO paga una tarifa menor. Se compara contra el WO más caro posible.
B23: 4. Tercerizado: tarifa del transportador + taladro a 1.456 USD/h por las horas de cada rango (12/18/24/28 h) + Truck Manager de 60 M COP por mes de campaña.
B24: 5. Si una movilización supera el tiempo cotizado (12/24/36/36 h) se paga el taladro por esas horas y además equipos y señalizadores por hora: unos 2.813 USD por hora en total. El WO no paga nada extra.
B25: 6. Bloqueos sociales y escolares durante movilizaciones: 22,25 h en 45 movilizaciones de 2025 (OpenWells, fase de movilización), es decir 22,25 × 35/45 = 17,3 h en una campaña de 35 pozos. En el tercerizado los paga SierraCol (condición 7 de la cotización 1255); en el WO no.
B26: 7. Petro Star normal: 50 % de descuento sobre su tarifa desde la 6ª movilización del mes. Lump Sum: sin descuento en la evaluación principal. Ecotransur: desde la 6ª solo cobra equipos.
B27: 8. Un mes sin poder mover con el contrato vigente paga el cargo fijo completo más el Truck Manager (Petro Star 177 k, Ecotransur 243 k). El fin de la campaña termina el contrato y no genera cobro.
B28: 9. Imprevistos y cobros adicionales: 0 % en ambos modelos (se asume que se compensan). TRM fija en 3.700. Sin IVA.
B29: 10. Las campañas reales de 2024 y 2025 se repiten movilización por movilización con las tarifas de julio de 2026 y las horas reales del log.
B31: 4. RESULTADOS (USD; ahorro = costo WO − costo tercerizado; positivo = el tercerizado cuesta menos)
B32: Escenario | C32: Petro Star tarifa normal (USD) | D32: Ecotransur (USD) | E32: Petro Star Lump Sum (USD) | F32: Nota
B33: Campaña proyectada, 5 movs/mes | C33: 132152.06 | D33: 490519.35 | E33: -472796.26 | F33: Valor fijo (no cambia al editar el Simulador). Ver Sensibilidad, sección 1.
B34: Campaña proyectada, 6 movs/mes | C34: 521560.55 | D34: 584485.57 | E34: -210864.81 | F34: Valor fijo (no cambia al editar el Simulador).
B35: Escenario cargado hoy en el Simulador | C35: =Simulador!D84 -> 132152.06 | D35: =Simulador!D87 -> 490519.35 | E35: =Simulador!D85 -> -472796.26 | F35: Enlace vivo: cambia al editar el Simulador.
B36: Campaña real 2025, horas reales | C36: ='Real 2025'!AA5 -> -70829.783 | D36: ='Real 2025'!AA8 -> -79162.904 | E36: ='Real 2025'!AA6 -> -1448687.2 | F36: Enlace vivo. Incluye equipos por horas excedidas.
B37: Campaña real 2024, horas reales | C37: ='Real 2024'!AA5 -> 1136023.3 | D37: ='Real 2024'!AA8 -> 996624.87 | E37: ='Real 2024'!AA6 -> -973152.06 | F37: Enlace vivo.
B38: En una campaña de 35 pozos (≈ 21 M USD a 600 k por pozo) el ahorro posible va de +0,13 M a +0,58 M: entre 4 k y 17 k por pozo, menos del 3 % del costo del pozo.
B40: 5. VENTAJAS Y DESVENTAJAS DE CADA MODELO
B41: Aspecto | C41: Work Order (directo) | E41: Tercerizado
B42: Costo por movilización | C42: Más alto por movilización. | E42: Más bajo por movilización, solo si se cumplen los tiempos y el mes llega a 5–6 movilizaciones.
B43: Demoras en la movilización | C43: Las absorbe el contratista: la tarifa tiene tope. | E43: Las paga SierraCol: taladro + equipos ≈ 2.813 USD por hora.
B44: Meses con pocas movilizaciones | C44: Sin costo fijo: se paga solo lo que se mueve. | E44: Cargo fijo de nómina y equipos hasta la 5ª movilización (Petro Star) o la 4ª (Ecotransur); descuento desde la 6ª.
B45: Bloqueos sociales o problemas operativos | C45: Sin costo adicional. | E45: Los paga SierraCol (condición 7); un mes sin mover cuesta 177 k (Petro Star) o 243 k (Ecotransur), con el Truck Manager.
B46: Gestión | C46: Un solo contratista responde por todo. | E46: Dos contratistas más el Truck Manager: la coordinación, la seguridad (HSE), las pólizas y la disponibilidad quedan a cargo de SierraCol.
...

Sheet Gráficas
B1: Gráficas del ejercicio
B2: Cada gráfico se alimenta de la tabla que tiene al lado. Las tablas en verde están enlazadas al Simulador o a las hojas Real; la de frecuencias es fija (motor de cálculo).
B4: 1. AHORRO DE LA CAMPAÑA DE 35 POZOS SEGÚN MOVILIZACIONES POR MES
B5: Movs/mes | C5: Petro Star tarifa normal | D5: Ecotransur | E5: Petro Star Lump Sum
B6: 4 | C6: -135092.52 | D6: 5451.8713 | E6: -740040.84
B7: 4,5 | C7: -2580.4417 | D7: 247985.61 | E7: -607528.76
B8: 5 | C8: 132152.06 | D8: 490519.35 | E8: -472796.26
B9: 5,5 | C9: 279484.05 | D9: 405025.86 | E9: -404125.29
B10: 6 | C10: 521560.55 | D10: 584485.57 | E10: -210864.81
B11: 6,5 | C11: 541571.5 | D11: 521411.53 | E11: -239669.88
B12: 7 | C12: 695332.35 | D12: 660216.65 | E12: -153696.06
B13: 8 | C13: 696138.76 | D13: 633612.89 | E13: -223453.67
B14: Con frecuencias no enteras se alternan meses; el último mes de la campaña puede quedar corto y pagar cargo fijo.
B24: 2. COSTO DE UNA MOVILIZACIÓN DE 0,1–5 km (USD, enlazado al Simulador)
B25: Concepto | C25: Tarifa | D25: Señalizadoras (WO) | E25: Taladro | F25: Truck Manager por movilización (60 M COP / movs del mes)
B26: Work Order | C26: =Simulador!D51-Simulador!D50 -> 98663 | D26: =Simulador!D50 -> 810.81081 | E26: 0 | F26: 0
B27: Petro Star 1ª–5ª | C27: =Simulador!D55 -> 59690.023 | D27: 0 | E27: =Simulador!D53 -> 26208 | F27: =IF(Simulador!$C$16="Mensual fijo",Simulador!$C$14/Simulador!$C$7/Simulador!$C$32,Simulador!$D$54) -> 3243.2432
B28: Petro Star 6ª+ | C28: =Simulador!D56 -> 29845.011 | D28: 0 | E28: =Simulador!D53 -> 26208 | F28: =IF(Simulador!$C$16="Mensual fijo",Simulador!$C$14/Simulador!$C$7/Simulador!$C$32,Simulador!$D$54) -> 3243.2432
B29: Ecotransur 1ª–5ª | C29: =Simulador!D59 -> 56135.946 | D29: 0 | E29: =Simulador!D53 -> 26208 | F29: =IF(Simulador!$C$16="Mensual fijo",Simulador!$C$14/Simulador!$C$7/Simulador!$C$32,Simulador!$D$54) -> 3243.2432
B30: Ecotransur 6ª+ | C30: =Simulador!D60 -> 33291.892 | D30: 0 | E30: =Simulador!D53 -> 26208 | F30: =IF(Simulador!$C$16="Mensual fijo",Simulador!$C$14/Simulador!$C$7/Simulador!$C$32,Simulador!$D$54) -> 3243.2432
B31: Lump Sum | C31: =Simulador!D57 -> 82239.105 | D31: 0 | E31: =Simulador!D53 -> 26208 | F31: =IF(Simulador!$C$16="Mensual fijo",Simulador!$C$14/Simulador!$C$7/Simulador!$C$32,Simulador!$D$54) -> 3243.2432
B44: 3. CAMPAÑA REAL 2025: AHORRO MES A MES CON HORAS REALES (USD, enlazado a Real 2025)
B45: Mes | C45: Movilizaciones | D45: Ahorro Petro Star tarifa normal (USD) | E45: Ahorro Ecotransur (USD)
B46: ='Real 2025'!K59 -> Feb | C46: ='Real 2025'!C59 -> 1 | D46: ='Real 2025'!P59 -> -225526.14 | E46: ='Real 2025'!Q59 -> -274611.91
B47: ='Real 2025'!K60 -> Mar | C47: ='Real 2025'!C60 -> 4 | D47: ='Real 2025'!P60 -> -62484.189 | E47: ='Real 2025'!Q60 -> -45916.027
B48: ='Real 2025'!K61 -> Abr | C48: ='Real 2025'!C61 -> 7 | D48: ='Real 2025'!P61 -> 108428.43 | E48: ='Real 2025'!Q61 -> 93105.254
B49: ='Real 2025'!K62 -> May | C49: ='Real 2025'!C62 -> 5 | D49: ='Real 2025'!P62 -> -84020.254 | E49: ='Real 2025'!Q62 -> -38102.786
B50: ='Real 2025'!K63 -> Jun | C50: ='Real 2025'!C63 -> 6 | D50: ='Real 2025'!P63 -> 94505.536 | E50: ='Real 2025'!Q63 -> 90516.126
B51: ='Real 2025'!K64 -> Jul | C51: ='Real 2025'!C64 -> 7 | D51: ='Real 2025'!P64 -> 91480.134 | E51: ='Real 2025'!Q64 -> 82316.943
B52: ='Real 2025'!K65 -> Ago | C52: ='Real 2025'!C65 -> 7 | D52: ='Real 2025'!P65 -> 78794.696 | E52: ='Real 2025'!Q65 -> 61024.322
B53: ='Real 2025'!K66 -> Sep | C53: ='Real 2025'!C66 -> 5 | D53: ='Real 2025'!P66 -> -4050.9332 | E53: ='Real 2025'!Q66 -> 35906.457
B54: ='Real 2025'!K67 -> Oct | C54: ='Real 2025'!C67 -> 3 | D54: ='Real 2025'!P67 -> -67957.062 | E54: ='Real 2025'!Q67 -> -83401.281
B64: 4. CAMPAÑA REAL 2024: AHORRO MES A MES CON HORAS REALES (USD, enlazado a Real 2024)
B65: Mes | C65: Movilizaciones | D65: Ahorro Petro Star tarifa normal (USD) | E65: Ahorro Ecotransur (USD)
B66: ='Real 2024'!K84 -> Ene | C66: ='Real 2024'!C84 -> 7 | D66: ='Real 2024'!P84 -> 140701.01 | E66: ='Real 2024'!Q84 -> 144343.27
B67: ='Real 2024'!K85 -> Feb | C67: ='Real 2024'!C85 -> 8 | D67: ='Real 2024'!P85 -> 203847.22 | E67: ='Real 2024'!Q85 -> 189864.32
B68: ='Real 2024'!K86 -> Mar | C68: ='Real 2024'!C86 -> 7 | D68: ='Real 2024'!P86 -> 40100.066 | E68: ='Real 2024'!Q86 -> 38540.747
B69: ='Real 2024'!K87 -> Abr | C69: ='Real 2024'!C87 -> 7 | D69: ='Real 2024'!P87 -> 128726.01 | E69: ='Real 2024'!Q87 -> 121387
B70: ='Real 2024'!K88 -> May | C70: ='Real 2024'!C88 -> 7 | D70: ='Real 2024'!P88 -> 139053.46 | E70: ='Real 2024'!Q88 -> 125627.6
B71: ='Real 2024'!K89 -> Jun | C71: ='Real 2024'!C89 -> 9 | D71: ='Real 2024'!P89 -> 221429.57 | E71: ='Real 2024'!Q89 -> 190235.94
...

Sheet Simulador
B1: Simulador de movilización del taladro GRS 110 · La Cira Infantas
B2: Work Order (suma global por movilización) frente a modelo tercerizado (transportador + taladro por hora + Truck Manager). Todo en USD salvo donde dice COP.
B3: Cómo leerlo: azul = dato editable · fondo amarillo = supuesto clave a confirmar · verde = viene de otra hoja · negro = cálculo. Ahorro positivo = el tercerizado cuesta menos que el Work Order.
B5: 1. PARÁMETROS GENERALES | K5: 1b. HORAS EXCEDIDAS, BLOQUEOS, TOPE DEL WO Y COSTO DEL POZO
B6: Variable | C6: Valor | D6: Unidad | E6: Clase | F6: Fuente | K6: Variable | N6: Valor
B7: TRM | C7: 3700 | D7: COP/USD | E7: Premisa SierraCol | F7: Tarifas.xlsx · E3 (fija para el ejercicio) | K7: ¿Se cobran equipos y señalizadores por hora por encima del tiempo estipulado? (Cot. 1255 p. 5) | N7: Sí
B8: Tarifa del taladro (24 h) | C8: 34944 | D8: USD/día | E8: Medido | F8: Tarifas.xlsx · E5 | K8: Señalizadores por hora excedida: 20 × 54.375 COP (Cot. 1255 p. 5) | N8: 1087500
B9: Tarifa del taladro por hora | C9: =C8/24 -> 1456 | D9: USD/h | E9: Cálculo | F9: Tarifas.xlsx · E6 (= E5/24) | K9: Meses bloqueados en la campaña (no se puede mover; contrato vigente) | N9: 0
B10: Oferta que se muestra en la fila 88 (solo detalle) | C10: Petro Star tarifa normal | E10: Selección | F10: Lista: las 3 ofertas (Lump Sum con y sin descuento) | K10: Ajuste a la tarifa WO (%) · las del Excel son el TOPE (movilización rápida); si tarda más paga una tarifa fija menor: solo 0 o negativo | N10: 0
B11: Adicionales sobre tarifa base (Petro Star normal y Ecotransur) | C11: 0 | D11: % | E11: Premisa SierraCol | F11: Tarifas.xlsx · E7. Se cancela con el WO; ver Pendientes | K11: Costo de un pozo en La Cira Infantas, solo perforación (USD) · SierraCol: 550–650 k | N11: 600000
B12: Adicionales sobre Lump Sum | C12: 0 | D12: % | E12: Premisa SierraCol | F12: Tarifas.xlsx · E8 | K12: Horas de bloqueo social o escolar durante movilizaciones en la campaña (OpenWells 2025: 22,25 h en 45 movilizaciones; se escala al número de pozos: 22,25 × pozos / 45) | N12: =22.25*C30/45 -> 17.305556
B13: Adicionales sobre Work Order | C13: 0 | D13: % | E13: Premisa SierraCol | F13: Simetría: los imprevistos también se pagan en el WO
B14: Truck Manager: valor mensual | C14: 60000000 | D14: COP/mes | E14: Medido | F14: Tarifas.xlsx · C29 = (60.000.000/E3)/6
B15: Truck Manager: movilizaciones/mes con que se prorratea | C15: 6 | D15: movs/mes | E15: Medido (fórmula Excel) | F15: Tarifas.xlsx · C29
B16: Truck Manager: forma de cobro | C16: Mensual fijo | E16: Premisa SierraCol | F16: Mensual fijo = 60 M COP por cada mes de campaña (criterio de la evaluación SierraCol v5). Por movilización = 2.702,70 USD (Excel C29)
B17: Descuento Petro Star tarifa normal desde la 6ª del mes | C17: 0.5 | D17: % | E17: Medido | F17: Cot. 1255 p. 2: '50% de cada escenario'
B18: Descuento Lump Sum (solo para la columna de referencia) | C18: 0.5 | D18: % | E18: Referencia aparte | F18: Evaluación principal: Lump Sum SIN descuento (SierraCol). Esta columna se muestra aparte
B19: Movilización del mes desde la que aplica el descuento | C19: 6 | D19: nº | E19: Medido | F19: Cot. 1255 p. 2 · Ecotransur p. 3–4
B20: Señalizadoras que faltan en el WO, por turno | C20: 4 | D20: personas | E20: Premisa SierraCol | F20: Ofertas: 10 por turno · WO: 6 por turno (dato SierraCol)
B21: Tarifa señalizador vial, turno 12 h | C21: 375000 | D21: COP/persona | E21: Medido | F21: Cot. 1255 p. 5, fila Señalizador vial, columna Turno 12 horas
B22: ¿Cargar el recargo de señalizadoras al Work Order? | C22: Sí | E22: Decisión de modelo | F22: Aplica a toda movilización: misma loc. 1 turno, demás rangos 2 turnos
B23: Reducción de la frecuencia por tiempo no productivo (NPT) de perforación | C23: 0 | D23: % | E23: Supuesto (sin dato) | F23: No hay plan de pozos ni NPT operativo en los archivos: se deja en 0 y se sensibiliza
B25: 2. CAMPAÑA A EVALUAR
B26: Variable | C26: Valor | D26: Unidad | E26: Clase | F26: Fuente
B27: Pozos en la misma localización | C27: 15 | D27: pozos | E27: Premisa SierraCol | F27: Proyección de campaña entregada por SierraCol
B28: Pozos en otra localización | C28: 20 | D28: pozos | E28: Premisa SierraCol | F28: Proyección de campaña entregada por SierraCol
B29: Rango de los pozos en otra localización (2 = 0,1–5 km · 3 = 5–10 km · 4 = más de 10 km) | C29: 2 | D29: =INDEX({"Misma localización","0,1–5 km","5–10 km","Más de 10 km"},C29) -> 0,1–5 km | E29: Premisa SierraCol | F29: Confirmado por SierraCol: 0,1–5 km
B30: Total de pozos (movilizaciones) | C30: =C27+C28 -> 35 | D30: pozos | E30: Cálculo | F30: Máximo 60 en la tabla de detalle
B31: Frecuencia mensual | C31: Constante | E31: Premisa SierraCol | F31: Esperado: 5 a 6 movs/mes (SierraCol). Perfil 2024 / Perfil 2025 = meses reales de los logs
B32: Movilizaciones por mes si la frecuencia es constante | C32: 5 | D32: movs/mes | E32: Premisa SierraCol | F32: Rango esperado 5–6; ver Sensibilidad (4 a 8)
B33: Perfil 2024: movilizaciones por mes (ene–nov, log) | C33: 7 | D33: 8 | E33: 7 | F33: 7 | G33: 7 | H33: 9 | I33: 7 | J33: 3 | K33: 6 | L33: 6 | M33: 3
B34: Perfil 2025: movilizaciones por mes (feb–oct, log) | C34: 1 | D34: 4 | E34: 7 | F34: 5 | G34: 6 | H34: 7 | I34: 7 | J34: 5 | K34: 3
B35: Los perfiles salen de Movilizaciones_2024.xlsx (C11:C21) y Movilizaciones_2025.xlsx (C11:C19). Los meses sin registro se tratan como campaña parada (premisa SierraCol) y no entran.
B37: 3. TARIFAS Y COSTO POR MOVILIZACIÓN, POR RANGO DE DISTANCIA
B38: Concepto | C38: Misma localización | D38: 0,1–5 km | E38: 5–10 km | F38: Más de 10 km | G38: Clase | H38: Fuente
B39: Horas de movilización que se le pagan al taladro (tercerizado) | C39: 12 | D39: 18 | E39: 24 | F39: 28 | G39: Dato del Excel | H39: Tarifas.xlsx · C26, C52, C78, C104
B40: Horas extra por movilización (NPT de movilización) | C40: 0 | D40: 0 | E40: 0 | F40: 0 | G40: Supuesto | H40: Logs: ver hojas Real 2024 / Real 2025
B41: Tiempo estipulado por el transportador (h): por encima se cobran equipos y señalizadores por hora | C41: 12 | D41: 24 | E41: 36 | F41: 36 | G41: Medido · Ecotransur = supuesto | H41: Cot. 1255 p. 1–2 'Tiempo total' y p. 5 (Ecotransur no declara tiempos)
B42: Turnos de señalizadoras por movilización | C42: 1 | D42: 2 | E42: 2 | F42: 2 | G42: Premisa SierraCol | H42: 12 h = 1 turno; 18/24/28 h = 2 turnos
B43: Work Order base (USD por movilización) | C43: 75642 | D43: 98663 | E43: 95374 | F43: 110174 | G43: Premisa SierraCol | H43: Tarifas.xlsx · K4:K7 (dato SierraCol)
...

Sheet Método
B1: Método: cómo está armado el costo de cada modelo y qué se cancela
B2: Se lee antes del Simulador. Lo que decide el resultado es cuántas movilizaciones caen en cada mes, no el promedio.
B4: 1. CLASIFICACIÓN DE CADA RENGLÓN DE COSTO
B5: Renglón | C5: Modelo | D5: Tipo | E5: Umbral | F5: Nota
B6: Tarifa por movilización (Work Order) | C6: Work Order | D6: Variable por movilización; escalón por rango | E6: Límites de rango 0,2 / 5 / 10 km | F6: No es monótona: 5–10 km (95.374) cuesta menos que 0,1–5 km (98.663).
B7: Tarifa con tope | C7: Work Order | D7: Acotada arriba y abajo | E7: Tope superior = tarifa del Excel (movilización rápida); si tarda más, tarifa fija menor | F7: El WO nunca paga más que la tarifa del Excel, tarde lo que tarde. Comparar contra el tope es el escenario más caro del WO, es decir, el más favorable al tercerizado.
B8: Recargo de señalizadoras faltantes | C8: Work Order | D8: Variable; escalón 1 o 2 turnos | E8: 12 h = 1 turno; más de 12 h = 2 turnos | F8: 4 personas por turno × 375.000 COP (Cot. 1255 p. 5).
B9: Tarifa del transportador | C9: Tercerizado | D9: Variable; escalón por rango | E9: Misma localización / 5 / 10 / 20 km | F9: Petro Star no cotiza más de 20 km: no hay tarifa por encima de ese límite.
B10: Descuento desde la 6ª del mes | C10: Tercerizado | D10: Salto según el número de la movilización en el mes | E10: 6ª movilización del mes | F10: Petro Star: 50 % de la tarifa. Ecotransur: solo equipos. Lump Sum: sin descuento (evaluación principal).
B11: Cargo fijo mensual (nómina + disponibilidad) | C11: Tercerizado | D11: Escalón decreciente; fijo mensual | E11: Petro Star 0–5 movs; Ecotransur 0–4 movs | F11: Petro Star todavía cobra con 5 movs (p. 4); Ecotransur no cobra desde la 5ª.
B12: Taladro durante la movilización | C12: Tercerizado | D12: Variable por hora | E12: Horas por rango (12/18/24/28) | F12: 34.944 USD/día. Bajo el WO no se paga (premisa SierraCol).
B13: Mes bloqueado (no se puede mover) | C13: Tercerizado | D13: Fijo mensual | E13: Mes con 0 movilizaciones y contrato vigente | F13: Petro Star 176.968 · Ecotransur 242.534 USD por mes (cargo de 0 movilizaciones + Truck Manager). Con el WO, 0.
B14: Truck Manager | C14: Tercerizado | D14: Fijo mensual (así se modela) | E14: 60 M COP por cada mes de campaña | F14: El Excel lo prorratea a 6 movs/mes (2.702,70 USD); con menos de 6 movs/mes ese prorrateo lo subestima. Por encima lo sobreestima.
B15: Horas excedidas sobre el tiempo estipulado | C15: Tercerizado | D15: Salto al pasar el tiempo cotizado | E15: Tiempo total 12/24/36/36 h | F15: Se paga el taladro por hora (1.456 USD) y además equipos y señalizadores por hora (~1.357 USD; Cot. 1255 p. 5). Con el WO, 0.
B16: Bandas de horas por ítem (Opción A/B) | C16: Tercerizado (Ecotransur) | D16: Salto por banda de horas | E16: 8–12 / ≤14 / 14–18 / 18–24 / ≤22 h | F16: El formato del Ítem 1 no viene adjunto: el Excel usa ítems 'más de X horas'.
B17: Personal, turnos o equipos fuera del mínimo | C17: Ambos | D17: Variable | E17: Lo que exceda el equipo mínimo | F17: Premisa: se cancela entre modelos (adicionales 0 %). Ver Pendientes.
B19: 2. ¿QUÉ VARIABLE AFECTA A LOS DOS MODELOS Y QUÉ SE CANCELA?
B20: Variable | C20: ¿A quién afecta? | D20: ¿Se cancela? | E20: Por qué
B21: Número de pozos de la campaña | C21: Ambos | D21: No | E21: El WO crece lineal; el tercerizado tiene umbrales mensuales. Entra completo al diferencial.
B22: Frecuencia mensual de movilizaciones | C22: Solo tercerizado | D22: No | E22: El WO cobra por movilización, no por mes. Es la variable que define la frontera.
B23: Rango de distancia | C23: Ambos, distinto | D23: No | E23: Las tarifas no se mueven igual: pasar de 0,1–5 a 5–10 km abarata el WO y encarece el tercerizado.
B24: Adicionales / imprevistos | C24: Ambos | D24: Sí (premisa) | E24: Se pone 0 % en ambos. Si no se cancelan, el residuo cae sobre el tercerizado (ver Sensibilidad).
B25: Taladro parado por NPT de perforación | C25: Ambos | D25: Sí | E25: La tarifa del taladro durante la perforación la rige su contrato en los dos modelos.
B26: Demoras dentro de la movilización | C26: Solo tercerizado | D26: No | E26: El WO es suma cerrada. En el tercerizado se paga el taladro por hora y, con Petro Star, equipos y nómina (cláusula 7).
B27: TRM | C27: Solo tercerizado | D27: No | E27: Las ofertas están en COP; el WO en USD. TRM alta favorece al tercerizado.
B28: Tarifa del taladro | C28: Solo tercerizado | D28: No | E28: Bajo el WO no se pagan horas de taladro.
B29: Señalizadoras | C29: Solo WO (recargo) | D29: No | E29: Las ofertas ya incluyen 20; el WO tiene 12.
B30: Truck Manager | C30: Solo tercerizado | D30: No | E30: Premisa SierraCol.
B32: 3. NPT: POR QUÉ CANAL AFECTA A CADA MODELO
B33: NPT de perforación (pozo): el taladro está parado o perforando más días. Su tarifa diaria se paga igual en los dos modelos, así que ese costo se cancela. Lo que NO se cancela es el efecto sobre la frecuencia: menos movilizaciones por mes. Al WO no le pasa nada (paga por movilización). Al tercerizado le cambia la factura: si el mes cae por debajo de 5 (Ecotransur) o de 6 (Petro Star), aparece el cargo fijo y se pierde el descuento. Canal: frecuencia, no horas.
B34: NPT de movilización (demora en el traslado): en el WO lo absorbe el contratista del taladro (suma global cerrada). En el tercerizado carga horas de taladro (1.456 USD/h) y, con Petro Star, si la demora no es atribuible al transportador, también equipos y nómina (Cot. 1255 p. 5, cláusula 7; a tarifas horarias de la p. 5 la flota mínima más 20 señalizadores suma unos 1.357 USD/h). Ecotransur no trae esa cláusula, pero factura aparte turnos extra. Canal: horas, residuo completo sobre el tercerizado.
B35: Lo único medido en los archivos es el sobretiempo de movilización de los logs (hojas Real 2024 / Real 2025): misma localización excede las 12 h del Excel en 10 de 23 movs (2024) y 10 de 11 (2025); 0,1–5 km excede las 18 h en 11 de 28 y 10 de 17; 5–10 km y más de 10 km en 2024 quedaron por debajo de lo supuesto. No hay NPT de perforación ni plan de pozos: se deja editable en 0 % (Simulador C23) y se muestra su sensibilidad.
B37: 4. VERIFICACIONES OBLIGATORIAS
B38: Verificación | C38: Resultado | D38: Detalle
B39: Recalcular fórmulas heredadas | C39: Hecho | D39: Las filas amarillas 'Costo Suma Global' (31, 57, 83, 109) se reproducen al centavo (hoja Reconciliación). El recargo de señalizadoras da 405,41 / 810,81 USD. El total WO de la campaña es 3.130.187 USD (= M18); la nota J55 cita 3.107.890.
B40: Monotonía de tarifas con la distancia | C40: Hallazgo | D40: Petro Star, Lump Sum y Ecotransur crecen con la distancia. El WO no: 5–10 km < 0,1–5 km. Si los 20 pozos fueran de 5–10 km, el ahorro de Petro Star cae unos 324.000 USD y el de Ecotransur unos 430.000 USD.
B41: Cobertura de más de 20 km | C41: Brecha | D41: Petro Star cotiza 10–20 km. El log 2024 tiene 1 movimiento de 22,1 km (pozo 5681); 2025 ninguno (máx. 14,6 km). Se valoró con la tarifa de 10–20 km y queda marcado.
B42: Horas de Petro Star vs Excel | C42: Diferencia | D42: Cotización: 12 / 24 / 36 / 36 h. Excel: 12 / 18 / 24 / 28 h. Por movilización: 0 / 8.736 / 17.472 / 11.648 USD de taladro. En la campaña base (20 pozos en 0,1–5 km): 174.720 USD. Editable en Simulador fila 39.
B43: IVA del Lump Sum | C43: Fuera de alcance | D43: Por instrucción de SierraCol se trabaja sin IVA. Si el IVA del 50 % de alquiler no fuera descontable, el Lump Sum costaría unos 225.000 USD más en la campaña base.
B44: Celdas sueltas F155 y F156 | C44: No usadas | D44: Valores 8 y 15 sin rótulo, dentro del bloque 5.6. No entran en ningún cálculo de este simulador.

Sheet Real 2024
B1: Campaña real 2024 · taladro GRS 110 · cómo habría funcionado cada modelo
B2: Movimientos de Movilizaciones_2024.xlsx (detalle, columnas D, C, F, G, H), en orden de fecha. Los meses sin registro no se cuentan (campaña parada). Parámetros y tarifas vienen de la hoja Simulador (verde). Columnas M–P usan las horas del Excel; Q–T, las horas reales del log. Ahorro positivo = el tercerizado cuesta menos.
W3: Modelo | X3: Costo con horas Excel (USD) | Y3: Ahorro con horas Excel (USD) | Z3: Costo con horas reales (USD) | AA3: Ahorro con horas reales (USD)
B4: Resumen | W4: Work Order | X4: =L79 -> 6424357.4 | Z4: =L79 -> 6424357.4
W5: Petro Star tarifa normal | X5: =M79+$H$95+$J$95 -> 5378820.6 | Y5: =$X$4-X5 -> 1045536.9 | Z5: =Q79+$H$95+$J$95 -> 5288334.2 | AA5: =$Z$4-Z5 -> 1136023.3
W6: Petro Star Lump Sum | X6: =N79+$H$95+$J$95 -> 7487995.9 | Y6: =$X$4-X6 -> -1063638.5 | Z6: =R79+$H$95+$J$95 -> 7397509.5 | AA6: =$Z$4-Z6 -> -973152.06
B7: Fecha | C7: Pozo | D7: Km | E7: Rango (log) | F7: Rango nº | G7: Mes | H7: Nº en el mes | I7: Horas reales | J7: Horas Excel | K7: Sobretiempo (h) | L7: Work Order (USD) | M7: Petro Star tarifa normal, horas Excel (USD) | N7: Petro Star Lump Sum, horas Excel (USD) | O7: Lump Sum con descuento (referencia), horas Excel (USD) | P7: Ecotransur, horas Excel (USD) | Q7: Petro Star tarifa normal, horas reales (USD) | R7: Petro Star Lump Sum, horas reales (USD) | S7: Lump Sum con descuento (referencia), horas reales (USD) | T7: Ecotransur, horas reales (USD) | U7: Nota | W7: Lump Sum con descuento (ref.) | X7: =O79+$H$95+$J$95 -> 6739376.7 | Y7: =$X$4-X7 -> -315019.27 | Z7: =S79+$H$95+$J$95 -> 6648890.3 | AA7: =$Z$4-Z7 -> -224532.87
B8: 45298 | C8: 5681 | D8: 22.1 | E8: 10+ km | F8: =MATCH(E8,{"Misma locación","0.15 - 5 km","5 - 10 km","10+ km"},0) -> 4 | G8: =MONTH(B8) -> 1 | H8: =COUNTIF($G$8:G8,G8) -> 1 | I8: 22 | J8: =INDEX(Simulador!$C$39:$F$39,F8) -> 28 | K8: =IF(I8="","",I8-J8) -> -6 | L8: =INDEX(Simulador!$C$51:$F$51,F8) -> 110984.81 | M8: =IF(H8>=Simulador!$C$19,INDEX(Simulador!$C$63:$F$63,F8),INDEX(Simulador!$C$62:$F$62,F8)) -> 107379.62 | N8: =INDEX(Simulador!$C$64:$F$64,F8) -> 152876.36 | O8: =IF(H8>=Simulador!$C$19,INDEX(Simulador!$C$65:$F$65,F8),INDEX(Simulador!$C$64:$F$64,F8)) -> 152876.36 | P8: =IF(H8>=Simulador!$C$19,INDEX(Simulador!$C$67:$F$67,F8),INDEX(Simulador!$C$66:$F$66,F8)) -> 109162.6 | Q8: =M8+(IF(I8="",J8+INDEX(Simulador!$C$40:$F$40,F8),I8)-J8-INDEX(Simulador!$C$40:$F$40,F8))*Simulador!$C$9-INDEX(Simulador!$C$69:$F$69,F8)+IF(Simulador!$N$7="Sí",MAX(0,IF(I8="",J8+INDEX(Simulador!$C$40:$F$40,F8),I8)-INDEX(Simulador!$C$41:$F$41,F8))*(INDEX(Simulador!$C$68:$F$68,F8)+Simulador!$N$8)/Simulador!$C$7,0) -> 98643.621 | R8: =N8+(IF(I8="",J8+INDEX(Simulador!$C$40:$F$40,F8),I8)-J8-INDEX(Simulador!$C$40:$F$40,F8))*Simulador!$C$9-INDEX(Simulador!$C$69:$F$69,F8)+IF(Simulador!$N$7="Sí",MAX(0,IF(I8="",J8+INDEX(Simulador!$C$40:$F$40,F8),I8)-INDEX(Simulador!$C$41:$F$41,F8))*(INDEX(Simulador!$C$68:$F$68,F8)+Simulador!$N$8)/Simulador!$C$7,0) -> 144140.36 | S8: =O8+(IF(I8="",J8+INDEX(Simulador!$C$40:$F$40,F8),I8)-J8-INDEX(Simulador!$C$40:$F$40,F8))*Simulador!$C$9-INDEX(Simulador!$C$69:$F$69,F8)+IF(Simulador!$N$7="Sí",MAX(0,IF(I8="",J8+INDEX(Simulador!$C$40:$F$40,F8),I8)-INDEX(Simulador!$C$41:$F$41,F8))*(INDEX(Simulador!$C$68:$F$68,F8)+Simulador!$N$8)/Simulador!$C$7,0) -> 144140.36 | T8: =P8+(IF(I8="",J8+INDEX(Simulador!$C$40:$F$40,F8),I8)-J8-INDEX(Simulador!$C$40:$F$40,F8))*Simulador!$C$9-INDEX(Simulador!$C$69:$F$69,F8)+IF(Simulador!$N$7="Sí",MAX(0,IF(I8="",J8+INDEX(Simulador!$C$40:$F$40,F8),I8)-INDEX(Simulador!$C$41:$F$41,F8))*(INDEX(Simulador!$C$68:$F$68,F8)+Simulador!$N$8)/Simulador!$C$7,0) -> 100426.6 | U8: Más de 20 km: Petro Star no tiene tarifa (se usa la de 10–20 km) | W8: Ecotransur | X8: =P79+$I$95+$J$95 -> 5518219 | Y8: =$X$4-X8 -> 906138.47 | Z8: =T79+$I$95+$J$95 -> 5427732.6 | AA8: =$Z$4-Z8 -> 996624.87
B9: 45301 | C9: 5270 | D9: 4.1 | E9: 0.15 - 5 km | F9: =MATCH(E9,{"Misma locación","0.15 - 5 km","5 - 10 km","10+ km"},0) -> 2 | G9: =MONTH(B9) -> 1 | H9: =COUNTIF($G$8:G9,G9) -> 2 | I9: 19.5 | J9: =INDEX(Simulador!$C$39:$F$39,F9) -> 18 | K9: =IF(I9="","",I9-J9) -> 1.5 | L9: =INDEX(Simulador!$C$51:$F$51,F9) -> 99473.811 | M9: =IF(H9>=Simulador!$C$19,INDEX(Simulador!$C$63:$F$63,F9),INDEX(Simulador!$C$62:$F$62,F9)) -> 85898.023 | N9: =INDEX(Simulador!$C$64:$F$64,F9) -> 108447.11 | O9: =IF(H9>=Simulador!$C$19,INDEX(Simulador!$C$65:$F$65,F9),INDEX(Simulador!$C$64:$F$64,F9)) -> 108447.11 | P9: =IF(H9>=Simulador!$C$19,INDEX(Simulador!$C$67:$F$67,F9),INDEX(Simulador!$C$66:$F$66,F9)) -> 82343.946 | Q9: =M9+(IF(I9="",J9+INDEX(Simulador!$C$40:$F$40,F9),I9)-J9-INDEX(Simulador!$C$40:$F$40,F9))*Simulador!$C$9-INDEX(Simulador!$C$69:$F$69,F9)+IF(Simulador!$N$7="Sí",MAX(0,IF(I9="",J9+INDEX(Simulador!$C$40:$F$40,F9),I9)-INDEX(Simulador!$C$41:$F$41,F9))*(INDEX(Simulador!$C$68:$F$68,F9)+Simulador!$N$8)/Simulador!$C$7,0) -> 88082.023 | R9: =N9+(IF(I9="",J9+INDEX(Simulador!$C$40:$F$40,F9),I9)-J9-INDEX(Simulador!$C$40:$F$40,F9))*Simulador!$C$9-INDEX(Simulador!$C$69:$F$69,F9)+IF(Simulador!$N$7="Sí",MAX(0,IF(I9="",J9+INDEX(Simulador!$C$40:$F$40,F9),I9)-INDEX(Simulador!$C$41:$F$41,F9))*(INDEX(Simulador!$C$68:$F$68,F9)+Simulador!$N$8)/Simulador!$C$7,0) -> 110631.11 | S9: =O9+(IF(I9="",J9+INDEX(Simulador!$C$40:$F$40,F9),I9)-J9-INDEX(Simulador!$C$40:$F$40,F9))*Simulador!$C$9-INDEX(Simulador!$C$69:$F$69,F9)+IF(Simulador!$N$7="Sí",MAX(0,IF(I9="",J9+INDEX(Simulador!$C$40:$F$40,F9),I9)-INDEX(Simulador!$C$41:$F$41,F9))*(INDEX(Simulador!$C$68:$F$68,F9)+Simulador!$N$8)/Simulador!$C$7,0) -> 110631.11 | T9: =P9+(IF(I9="",J9+INDEX(Simulador!$C$40:$F$40,F9),I9)-J9-INDEX(Simulador!$C$40:$F$40,F9))*Simulador!$C$9-INDEX(Simulador!$C$69:$F$69,F9)+IF(Simulador!$N$7="Sí",MAX(0,IF(I9="",J9+INDEX(Simulador!$C$40:$F$40,F9),I9)-INDEX(Simulador!$C$41:$F$41,F9))*(INDEX(Simulador!$C$68:$F$68,F9)+Simulador!$N$8)/Simulador!$C$7,0) -> 84527.946 | W9: Movilizaciones | X9: =COUNT(B8:B77) -> 70
B10: 45305 | C10: 5077 | D10: 4.1 | E10: 0.15 - 5 km | F10: =MATCH(E10,{"Misma locación","0.15 - 5 km","5 - 10 km","10+ km"},0) -> 2 | G10: =MONTH(B10) -> 1 | H10: =COUNTIF($G$8:G10,G10) -> 3 | I10: 15.75 | J10: =INDEX(Simulador!$C$39:$F$39,F10) -> 18 | K10: =IF(I10="","",I10-J10) -> -2.25 | L10: =INDEX(Simulador!$C$51:$F$51,F10) -> 99473.811 | M10: =IF(H10>=Simulador!$C$19,INDEX(Simulador!$C$63:$F$63,F10),INDEX(Simulador!$C$62:$F$62,F10)) -> 85898.023 | N10: =INDEX(Simulador!$C$64:$F$64,F10) -> 108447.11 | O10: =IF(H10>=Simulador!$C$19,INDEX(Simulador!$C$65:$F$65,F10),INDEX(Simulador!$C$64:$F$64,F10)) -> 108447.11 | P10: =IF(H10>=Simulador!$C$19,INDEX(Simulador!$C$67:$F$67,F10),INDEX(Simulador!$C$66:$F$66,F10)) -> 82343.946 | Q10: =M10+(IF(I10="",J10+INDEX(Simulador!$C$40:$F$40,F10),I10)-J10-INDEX(Simulador!$C$40:$F$40,F10))*Simulador!$C$9-INDEX(Simulador!$C$69:$F$69,F10)+IF(Simulador!$N$7="Sí",MAX(0,IF(I10="",J10+INDEX(Simulador!$C$40:$F$40,F10),I10)-INDEX(Simulador!$C$41:$F$41,F10))*(INDEX(Simulador!$C$68:$F$68,F10)+Simulador!$N$8)/Simulador!$C$7,0) -> 82622.023 | R10: =N10+(IF(I10="",J10+INDEX(Simulador!$C$40:$F$40,F10),I10)-J10-INDEX(Simulador!$C$40:$F$40,F10))*Simulador!$C$9-INDEX(Simulador!$C$69:$F$69,F10)+IF(Simulador!$N$7="Sí",MAX(0,IF(I10="",J10+INDEX(Simulador!$C$40:$F$40,F10),I10)-INDEX(Simulador!$C$41:$F$41,F10))*(INDEX(Simulador!$C$68:$F$68,F10)+Simulador!$N$8)/Simulador!$C$7,0) -> 105171.11 | S10: =O10+(IF(I10="",J10+INDEX(Simulador!$C$40:$F$40,F10),I10)-J10-INDEX(Simulador!$C$40:$F$40,F10))*Simulador!$C$9-INDEX(Simulador!$C$69:$F$69,F10)+IF(Simulador!$N$7="Sí",MAX(0,IF(I10="",J10+INDEX(Simulador!$C$40:$F$40,F10),I10)-INDEX(Simulador!$C$41:$F$41,F10))*(INDEX(Simulador!$C$68:$F$68,F10)+Simulador!$N$8)/Simulador!$C$7,0) -> 105171.11 | T10: =P10+(IF(I10="",J10+INDEX(Simulador!$C$40:$F$40,F10),I10)-J10-INDEX(Simulador!$C$40:$F$40,F10))*Simulador!$C$9-INDEX(Simulador!$C$69:$F$69,F10)+IF(Simulador!$N$7="Sí",MAX(0,IF(I10="",J10+INDEX(Simulador!$C$40:$F$40,F10),I10)-INDEX(Simulador!$C$41:$F$41,F10))*(INDEX(Simulador!$C$68:$F$68,F10)+Simulador!$N$8)/Simulador!$C$7,0) -> 79067.946 | W10: Meses con movilizaciones | X10: =COUNTIF(C84:C94,">0") -> 11
B11: 45309 | C11: 5136 | D11: 3.25 | E11: 0.15 - 5 km | F11: =MATCH(E11,{"Misma locación","0.15 - 5 km","5 - 10 km","10+ km"},0) -> 2 | G11: =MONTH(B11) -> 1 | H11: =COUNTIF($G$8:G11,G11) -> 4 | J11: =INDEX(Simulador!$C$39:$F$39,F11) -> 18 | K11: =IF(I11="","",I11-J11) | L11: =INDEX(Simulador!$C$51:$F$51,F11) -> 99473.811 | M11: =IF(H11>=Simulador!$C$19,INDEX(Simulador!$C$63:$F$63,F11),INDEX(Simulador!$C$62:$F$62,F11)) -> 85898.023 | N11: =INDEX(Simulador!$C$64:$F$64,F11) -> 108447.11 | O11: =IF(H11>=Simulador!$C$19,INDEX(Simulador!$C$65:$F$65,F11),INDEX(Simulador!$C$64:$F$64,F11)) -> 108447.11 | P11: =IF(H11>=Simulador!$C$19,INDEX(Simulador!$C$67:$F$67,F11),INDEX(Simulador!$C$66:$F$66,F11)) -> 82343.946 | Q11: =M11+(IF(I11="",J11+INDEX(Simulador!$C$40:$F$40,F11),I11)-J11-INDEX(Simulador!$C$40:$F$40,F11))*Simulador!$C$9-INDEX(Simulador!$C$69:$F$69,F11)+IF(Simulador!$N$7="Sí",MAX(0,IF(I11="",J11+INDEX(Simulador!$C$40:$F$40,F11),I11)-INDEX(Simulador!$C$41:$F$41,F11))*(INDEX(Simulador!$C$68:$F$68,F11)+Simulador!$N$8)/Simulador!$C$7,0) -> 85898.023 | R11: =N11+(IF(I11="",J11+INDEX(Simulador!$C$40:$F$40,F11),I11)-J11-INDEX(Simulador!$C$40:$F$40,F11))*Simulador!$C$9-INDEX(Simulador!$C$69:$F$69,F11)+IF(Simulador!$N$7="Sí",MAX(0,IF(I11="",J11+INDEX(Simulador!$C$40:$F$40,F11),I11)-INDEX(Simulador!$C$41:$F$41,F11))*(INDEX(Simulador!$C$68:$F$68,F11)+Simulador!$N$8)/Simulador!$C$7,0) -> 108447.11 | S11: =O11+(IF(I11="",J11+INDEX(Simulador!$C$40:$F$40,F11),I11)-J11-INDEX(Simulador!$C$40:$F$40,F11))*Simulador!$C$9-INDEX(Simulador!$C$69:$F$69,F11)+IF(Simulador!$N$7="Sí",MAX(0,IF(I11="",J11+INDEX(Simulador!$C$40:$F$40,F11),I11)-INDEX(Simulador!$C$41:$F$41,F11))*(INDEX(Simulador!$C$68:$F$68,F11)+Simulador!$N$8)/Simulador!$C$7,0) -> 108447.11 | T11: =P11+(IF(I11="",J11+INDEX(Simulador!$C$40:$F$40,F11),I11)-J11-INDEX(Simulador!$C$40:$F$40,F11))*Simulador!$C$9-INDEX(Simulador!$C$69:$F$69,F11)+IF(Simulador!$N$7="Sí",MAX(0,IF(I11="",J11+INDEX(Simulador!$C$40:$F$40,F11),I11)-INDEX(Simulador!$C$41:$F$41,F11))*(INDEX(Simulador!$C$68:$F$68,F11)+Simulador!$N$8)/Simulador!$C$7,0) -> 82343.946 | U11: Sin horas en el log: se usan las del Excel | W11: Promedio movs/mes (meses activos) | X11: =X9/X10 -> 6.3636364
B12: 45312 | C12: 5106 | D12: 4.9 | E12: 0.15 - 5 km | F12: =MATCH(E12,{"Misma locación","0.15 - 5 km","5 - 10 km","10+ km"},0) -> 2 | G12: =MONTH(B12) -> 1 | H12: =COUNTIF($G$8:G12,G12) -> 5 | I12: 20 | J12: =INDEX(Simulador!$C$39:$F$39,F12) -> 18 | K12: =IF(I12="","",I12-J12) -> 2 | L12: =INDEX(Simulador!$C$51:$F$51,F12) -> 99473.811 | M12: =IF(H12>=Simulador!$C$19,INDEX(Simulador!$C$63:$F$63,F12),INDEX(Simulador!$C$62:$F$62,F12)) -> 85898.023 | N12: =INDEX(Simulador!$C$64:$F$64,F12) -> 108447.11 | O12: =IF(H12>=Simulador!$C$19,INDEX(Simulador!$C$65:$F$65,F12),INDEX(Simulador!$C$64:$F$64,F12)) -> 108447.11 | P12: =IF(H12>=Simulador!$C$19,INDEX(Simulador!$C$67:$F$67,F12),INDEX(Simulador!$C$66:$F$66,F12)) -> 82343.946 | Q12: =M12+(IF(I12="",J12+INDEX(Simulador!$C$40:$F$40,F12),I12)-J12-INDEX(Simulador!$C$40:$F$40,F12))*Simulador!$C$9-INDEX(Simulador!$C$69:$F$69,F12)+IF(Simulador!$N$7="Sí",MAX(0,IF(I12="",J12+INDEX(Simulador!$C$40:$F$40,F12),I12)-INDEX(Simulador!$C$41:$F$41,F12))*(INDEX(Simulador!$C$68:$F$68,F12)+Simulador!$N$8)/Simulador!$C$7,0) -> 88810.023 | R12: =N12+(IF(I12="",J12+INDEX(Simulador!$C$40:$F$40,F12),I12)-J12-INDEX(Simulador!$C$40:$F$40,F12))*Simulador!$C$9-INDEX(Simulador!$C$69:$F$69,F12)+IF(Simulador!$N$7="Sí",MAX(0,IF(I12="",J12+INDEX(Simulador!$C$40:$F$40,F12),I12)-INDEX(Simulador!$C$41:$F$41,F12))*(INDEX(Simulador!$C$68:$F$68,F12)+Simulador!$N$8)/Simulador!$C$7,0) -> 111359.11 | S12: =O12+(IF(I12="",J12+INDEX(Simulador!$C$40:$F$40,F12),I12)-J12-INDEX(Simulador!$C$40:$F$40,F12))*Simulador!$C$9-INDEX(Simulador!$C$69:$F$69,F12)+IF(Simulador!$N$7="Sí",MAX(0,IF(I12="",J12+INDEX(Simulador!$C$40:$F$40,F12),I12)-INDEX(Simulador!$C$41:$F$41,F12))*(INDEX(Simulador!$C$68:$F$68,F12)+Simulador!$N$8)/Simulador!$C$7,0) -> 111359.11 | T12: =P12+(IF(I12="",J12+INDEX(Simulador!$C$40:$F$40,F12),I12)-J12-INDEX(Simulador!$C$40:$F$40,F12))*Simulador!$C$9-INDEX(Simulador!$C$69:$F$69,F12)+IF(Simulador!$N$7="Sí",MAX(0,IF(I12="",J12+INDEX(Simulador!$C$40:$F$40,F12),I12)-INDEX(Simulador!$C$41:$F$41,F12))*(INDEX(Simulador!$C$68:$F$68,F12)+Simulador!$N$8)/Simulador!$C$7,0) -> 85255.946 | W12: Meses con 6 o más movilizaciones | X12: =COUNTIF(C84:C94,">=6") -> 9
B13: 45317 | C13: 5067 | D13: 0.4 | E13: 0.15 - 5 km | F13: =MATCH(E13,{"Misma locación","0.15 - 5 km","5 - 10 km","10+ km"},0) -> 2 | G13: =MONTH(B13) -> 1 | H13: =COUNTIF($G$8:G13,G13) -> 6 | I13: 12.5 | J13: =INDEX(Simulador!$C$39:$F$39,F13) -> 18 | K13: =IF(I13="","",I13-J13) -> -5.5 | L13: =INDEX(Simulador!$C$51:$F$51,F13) -> 99473.811 | M13: =IF(H13>=Simulador!$C$19,INDEX(Simulador!$C$63:$F$63,F13),INDEX(Simulador!$C$62:$F$62,F13)) -> 56053.011 | N13: =INDEX(Simulador!$C$64:$F$64,F13) -> 108447.11 | O13: =IF(H13>=Simulador!$C$19,INDEX(Simulador!$C$65:$F$65,F13),INDEX(Simulador!$C$64:$F$64,F13)) -> 67327.553 | P13: =IF(H13>=Simulador!$C$19,INDEX(Simulador!$C$67:$F$67,F13),INDEX(Simulador!$C$66:$F$66,F13)) -> 59499.892 | Q13: =M13+(IF(I13="",J13+INDEX(Simulador!$C$40:$F$40,F13),I13)-J13-INDEX(Simulador!$C$40:$F$40,F13))*Simulador!$C$9-INDEX(Simulador!$C$69:$F$69,F13)+IF(Simulador!$N$7="Sí",MAX(0,IF(I13="",J13+INDEX(Simulador!$C$40:$F$40,F13),I13)-INDEX(Simulador!$C$41:$F$41,F13))*(INDEX(Simulador!$C$68:$F$68,F13)+Simulador!$N$8)/Simulador!$C$7,0) -> 48045.011 | R13: =N13+(IF(I13="",J13+INDEX(Simulador!$C$40:$F$40,F13),I13)-J13-INDEX(Simulador!$C$40:$F$40,F13))*Simulador!$C$9-INDEX(Simulador!$C$69:$F$69,F13)+IF(Simulador!$N$7="Sí",MAX(0,IF(I13="",J13+INDEX(Simulador!$C$40:$F$40,F13),I13)-INDEX(Simulador!$C$41:$F$41,F13))*(INDEX(Simulador!$C$68:$F$68,F13)+Simulador!$N$8)/Simulador!$C$7,0) -> 100439.11 | S13: =O13+(IF(I13="",J13+INDEX(Simulador!$C$40:$F$40,F13),I13)-J13-INDEX(Simulador!$C$40:$F$40,F13))*Simulador!$C$9-INDEX(Simulador!$C$69:$F$69,F13)+IF(Simulador!$N$7="Sí",MAX(0,IF(I13="",J13+INDEX(Simulador!$C$40:$F$40,F13),I13)-INDEX(Simulador!$C$41:$F$41,F13))*(INDEX(Simulador!$C$68:$F$68,F13)+Simulador!$N$8)/Simulador!$C$7,0) -> 59319.553 | T13: =P13+(IF(I13="",J13+INDEX(Simulador!$C$40:$F$40,F13),I13)-J13-INDEX(Simulador!$C$40:$F$40,F13))*Simulador!$C$9-INDEX(Simulador!$C$69:$F$69,F13)+IF(Simulador!$N$7="Sí",MAX(0,IF(I13="",J13+INDEX(Simulador!$C$40:$F$40,F13),I13)-INDEX(Simulador!$C$41:$F$41,F13))*(INDEX(Simulador!$C$68:$F$68,F13)+Simulador!$N$8)/Simulador!$C$7,0) -> 51491.892 | W13: Meses con menos de 5 movilizaciones | X13: =COUNTIF(C84:C94,"<5") -> 2
B14: 45321 | C14: 5023 | D14: 5.2 | E14: 5 - 10 km | F14: =MATCH(E14,{"Misma locación","0.15 - 5 km","5 - 10 km","10+ km"},0) -> 3 | G14: =MONTH(B14) -> 1 | H14: =COUNTIF($G$8:G14,G14) -> 7 | I14: 16 | J14: =INDEX(Simulador!$C$39:$F$39,F14) -> 24 | K14: =IF(I14="","",I14-J14) -> -8 | L14: =INDEX(Simulador!$C$51:$F$51,F14) -> 96184.811 | M14: =IF(H14>=Simulador!$C$19,INDEX(Simulador!$C$63:$F$63,F14),INDEX(Simulador!$C$62:$F$62,F14)) -> 67168.729 | N14: =INDEX(Simulador!$C$64:$F$64,F14) -> 135930.45 | O14: =IF(H14>=Simulador!$C$19,INDEX(Simulador!$C$65:$F$65,F14),INDEX(Simulador!$C$64:$F$64,F14)) -> 85437.226 | P14: =IF(H14>=Simulador!$C$19,INDEX(Simulador!$C$67:$F$67,F14),INDEX(Simulador!$C$66:$F$66,F14)) -> 72512.919 | Q14: =M14+(IF(I14="",J14+INDEX(Simulador!$C$40:$F$40,F14),I14)-J14-INDEX(Simulador!$C$40:$F$40,F14))*Simulador!$C$9-INDEX(Simulador!$C$69:$F$69,F14)+IF(Simulador!$N$7="Sí",MAX(0,IF(I14="",J14+INDEX(Simulador!$C$40:$F$40,F14),I14)-INDEX(Simulador!$C$41:$F$41,F14))*(INDEX(Simulador!$C$68:$F$68,F14)+Simulador!$N$8)/Simulador!$C$7,0) -> 55520.729 | R14: =N14+(IF(I14="",J14+INDEX(Simulador!$C$40:$F$40,F14),I14)-J14-INDEX(Simulador!$C$40:$F$40,F14))*Simulador!$C$9-INDEX(Simulador!$C$69:$F$69,F14)+IF(Simulador!$N$7="Sí",MAX(0,IF(I14="",J14+INDEX(Simulador!$C$40:$F$40,F14),I14)-INDEX(Simulador!$C$41:$F$41,F14))*(INDEX(Simulador!$C$68:$F$68,F14)+Simulador!$N$8)/Simulador!$C$7,0) -> 124282.45 | S14: =O14+(IF(I14="",J14+INDEX(Simulador!$C$40:$F$40,F14),I14)-J14-INDEX(Simulador!$C$40:$F$40,F14))*Simulador!$C$9-INDEX(Simulador!$C$69:$F$69,F14)+IF(Simulador!$N$7="Sí",MAX(0,IF(I14="",J14+INDEX(Simulador!$C$40:$F$40,F14),I14)-INDEX(Simulador!$C$41:$F$41,F14))*(INDEX(Simulador!$C$68:$F$68,F14)+Simulador!$N$8)/Simulador!$C$7,0) -> 73789.226 | T14: =P14+(IF(I14="",J14+INDEX(Simulador!$C$40:$F$40,F14),I14)-J14-INDEX(Simulador!$C$40:$F$40,F14))*Simulador!$C$9-INDEX(Simulador!$C$69:$F$69,F14)+IF(Simulador!$N$7="Sí",MAX(0,IF(I14="",J14+INDEX(Simulador!$C$40:$F$40,F14),I14)-INDEX(Simulador!$C$41:$F$41,F14))*(INDEX(Simulador!$C$68:$F$68,F14)+Simulador!$N$8)/Simulador!$C$7,0) -> 60864.919
B15: 45325 | C15: 5002 | D15: 0.0064007998 | E15: Misma locación | F15: =MATCH(E15,{"Misma locación","0.15 - 5 km","5 - 10 km","10+ km"},0) -> 1 | G15: =MONTH(B15) -> 2 | H15: =COUNTIF($G$8:G15,G15) -> 1 | I15: 8 | J15: =INDEX(Simulador!$C$39:$F$39,F15) -> 12 | K15: =IF(I15="","",I15-J15) -> -4 | L15: =INDEX(Simulador!$C$51:$F$51,F15) -> 76047.405 | M15: =IF(H15>=Simulador!$C$19,INDEX(Simulador!$C$63:$F$63,F15),INDEX(Simulador!$C$62:$F$62,F15)) -> 55414.011 | N15: =INDEX(Simulador!$C$64:$F$64,F15) -> 65678.455 | O15: =IF(H15>=Simulador!$C$19,INDEX(Simulador!$C$65:$F$65,F15),INDEX(Simulador!$C$64:$F$64,F15)) -> 65678.455 | P15: =IF(H15>=Simulador!$C$19,INDEX(Simulador!$C$67:$F$67,F15),INDEX(Simulador!$C$66:$F$66,F15)) -> 55372.811 | Q15: =M15+(IF(I15="",J15+INDEX(Simulador!$C$40:$F$40,F15),I15)-J15-INDEX(Simulador!$C$40:$F$40,F15))*Simulador!$C$9-INDEX(Simulador!$C$69:$F$69,F15)+IF(Simulador!$N$7="Sí",MAX(0,IF(I15="",J15+INDEX(Simulador!$C$40:$F$40,F15),I15)-INDEX(Simulador!$C$41:$F$41,F15))*(INDEX(Simulador!$C$68:$F$68,F15)+Simulador!$N$8)/Simulador!$C$7,0) -> 49590.011 | R15: =N15+(IF(I15="",J15+INDEX(Simulador!$C$40:$F$40,F15),I15)-J15-INDEX(Simulador!$C$40:$F$40,F15))*Simulador!$C$9-INDEX(Simulador!$C$69:$F$69,F15)+IF(Simulador!$N$7="Sí",MAX(0,IF(I15="",J15+INDEX(Simulador!$C$40:$F$40,F15),I15)-INDEX(Simulador!$C$41:$F$41,F15))*(INDEX(Simulador!$C$68:$F$68,F15)+Simulador!$N$8)/Simulador!$C$7,0) -> 59854.455 | S15: =O15+(IF(I15="",J15+INDEX(Simulador!$C$40:$F$40,F15),I15)-J15-INDEX(Simulador!$C$40:$F$40,F15))*Simulador!$C$9-INDEX(Simulador!$C$69:$F$69,F15)+IF(Simulador!$N$7="Sí",MAX(0,IF(I15="",J15+INDEX(Simulador!$C$40:$F$40,F15),I15)-INDEX(Simulador!$C$41:$F$41,F15))*(INDEX(Simulador!$C$68:$F$68,F15)+Simulador!$N$8)/Simulador!$C$7,0) -> 59854.455 | T15: =P15+(IF(I15="",J15+INDEX(Simulador!$C$40:$F$40,F15),I15)-J15-INDEX(Simulador!$C$40:$F$40,F15))*Simulador!$C$9-INDEX(Simulador!$C$69:$F$69,F15)+IF(Simulador!$N$7="Sí",MAX(0,IF(I15="",J15+INDEX(Simulador!$C$40:$F$40,F15),I15)-INDEX(Simulador!$C$41:$F$41,F15))*(INDEX(Simulador!$C$68:$F$68,F15)+Simulador!$N$8)/Simulador!$C$7,0) -> 49548.811
B16: 45328 | C16: 5009 | D16: 3 | E16: 0.15 - 5 km | F16: =MATCH(E16,{"Misma locación","0.15 - 5 km","5 - 10 km","10+ km"},0) -> 2 | G16: =MONTH(B16) -> 2 | H16: =COUNTIF($G$8:G16,G16) -> 2 | I16: 22 | J16: =INDEX(Simulador!$C$39:$F$39,F16) -> 18 | K16: =IF(I16="","",I16-J16) -> 4 | L16: =INDEX(Simulador!$C$51:$F$51,F16) -> 99473.811 | M16: =IF(H16>=Simulador!$C$19,INDEX(Simulador!$C$63:$F$63,F16),INDEX(Simulador!$C$62:$F$62,F16)) -> 85898.023 | N16: =INDEX(Simulador!$C$64:$F$64,F16) -> 108447.11 | O16: =IF(H16>=Simulador!$C$19,INDEX(Simulador!$C$65:$F$65,F16),INDEX(Simulador!$C$64:$F$64,F16)) -> 108447.11 | P16: =IF(H16>=Simulador!$C$19,INDEX(Simulador!$C$67:$F$67,F16),INDEX(Simulador!$C$66:$F$66,F16)) -> 82343.946 | Q16: =M16+(IF(I16="",J16+INDEX(Simulador!$C$40:$F$40,F16),I16)-J16-INDEX(Simulador!$C$40:$F$40,F16))*Simulador!$C$9-INDEX(Simulador!$C$69:$F$69,F16)+IF(Simulador!$N$7="Sí",MAX(0,IF(I16="",J16+INDEX(Simulador!$C$40:$F$40,F16),I16)-INDEX(Simulador!$C$41:$F$41,F16))*(INDEX(Simulador!$C$68:$F$68,F16)+Simulador!$N$8)/Simulador!$C$7,0) -> 91722.023 | R16: =N16+(IF(I16="",J16+INDEX(Simulador!$C$40:$F$40,F16),I16)-J16-INDEX(Simulador!$C$40:$F$40,F16))*Simulador!$C$9-INDEX(Simulador!$C$69:$F$69,F16)+IF(Simulador!$N$7="Sí",MAX(0,IF(I16="",J16+INDEX(Simulador!$C$40:$F$40,F16),I16)-INDEX(Simulador!$C$41:$F$41,F16))*(INDEX(Simulador!$C$68:$F$68,F16)+Simulador!$N$8)/Simulador!$C$7,0) -> 114271.11 | S16: =O16+(IF(I16="",J16+INDEX(Simulador!$C$40:$F$40,F16),I16)-J16-INDEX(Simulador!$C$40:$F$40,F16))*Simulador!$C$9-INDEX(Simulador!$C$69:$F$69,F16)+IF(Simulador!$N$7="Sí",MAX(0,IF(I16="",J16+INDEX(Simulador!$C$40:$F$40,F16),I16)-INDEX(Simulador!$C$41:$F$41,F16))*(INDEX(Simulador!$C$68:$F$68,F16)+Simulador!$N$8)/Simulador!$C$7,0) -> 114271.11 | T16: =P16+(IF(I16="",J16+INDEX(Simulador!$C$40:$F$40,F16),I16)-J16-INDEX(Simulador!$C$40:$F$40,F16))*Simulador!$C$9-INDEX(Simulador!$C$69:$F$69,F16)+IF(Simulador!$N$7="Sí",MAX(0,IF(I16="",J16+INDEX(Simulador!$C$40:$F$40,F16),I16)-INDEX(Simulador!$C$41:$F$41,F16))*(INDEX(Simulador!$C$68:$F$68,F16)+Simulador!$N$8)/Simulador!$C$7,0) -> 88167.946
B17: 45331 | C17: 5200 | D17: 0.02 | E17: Misma locación | F17: =MATCH(E17,{"Misma locación","0.15 - 5 km","5 - 10 km","10+ km"},0) -> 1 | G17: =MONTH(B17) -> 2 | H17: =COUNTIF($G$8:G17,G17) -> 3 | I17: 10 | J17: =INDEX(Simulador!$C$39:$F$39,F17) -> 12 | K17: =IF(I17="","",I17-J17) -> -2 | L17: =INDEX(Simulador!$C$51:$F$51,F17) -> 76047.405 | M17: =IF(H17>=Simulador!$C$19,INDEX(Simulador!$C$63:$F$63,F17),INDEX(Simulador!$C$62:$F$62,F17)) -> 55414.011 | N17: =INDEX(Simulador!$C$64:$F$64,F17) -> 65678.455 | O17: =IF(H17>=Simulador!$C$19,INDEX(Simulador!$C$65:$F$65,F17),INDEX(Simulador!$C$64:$F$64,F17)) -> 65678.455 | P17: =IF(H17>=Simulador!$C$19,INDEX(Simulador!$C$67:$F$67,F17),INDEX(Simulador!$C$66:$F$66,F17)) -> 55372.811 | Q17: =M17+(IF(I17="",J17+INDEX(Simulador!$C$40:$F$40,F17),I17)-J17-INDEX(Simulador!$C$40:$F$40,F17))*Simulador!$C$9-INDEX(Simulador!$C$69:$F$69,F17)+IF(Simulador!$N$7="Sí",MAX(0,IF(I17="",J17+INDEX(Simulador!$C$40:$F$40,F17),I17)-INDEX(Simulador!$C$41:$F$41,F17))*(INDEX(Simulador!$C$68:$F$68,F17)+Simulador!$N$8)/Simulador!$C$7,0) -> 52502.011 | R17: =N17+(IF(I17="",J17+INDEX(Simulador!$C$40:$F$40,F17),I17)-J17-INDEX(Simulador!$C$40:$F$40,F17))*Simulador!$C$9-INDEX(Simulador!$C$69:$F$69,F17)+IF(Simulador!$N$7="Sí",MAX(0,IF(I17="",J17+INDEX(Simulador!$C$40:$F$40,F17),I17)-INDEX(Simulador!$C$41:$F$41,F17))*(INDEX(Simulador!$C$68:$F$68,F17)+Simulador!$N$8)/Simulador!$C$7,0) -> 62766.455 | S17: =O17+(IF(I17="",J17+INDEX(Simulador!$C$40:$F$40,F17),I17)-J17-INDEX(Simulador!$C$40:$F$40,F17))*Simulador!$C$9-INDEX(Simulador!$C$69:$F$69,F17)+IF(Simulador!$N$7="Sí",MAX(0,IF(I17="",J17+INDEX(Simulador!$C$40:$F$40,F17),I17)-INDEX(Simulador!$C$41:$F$41,F17))*(INDEX(Simulador!$C$68:$F$68,F17)+Simulador!$N$8)/Simulador!$C$7,0) -> 62766.455 | T17: =P17+(IF(I17="",J17+INDEX(Simulador!$C$40:$F$40,F17),I17)-J17-INDEX(Simulador!$C$40:$F$40,F17))*Simulador!$C$9-INDEX(Simulador!$C$69:$F$69,F17)+IF(Simulador!$N$7="Sí",MAX(0,IF(I17="",J17+INDEX(Simulador!$C$40:$F$40,F17),I17)-INDEX(Simulador!$C$41:$F$41,F17))*(INDEX(Simulador!$C$68:$F$68,F17)+Simulador!$N$8)/Simulador!$C$7,0) -> 52460.811
B18: 45334 | C18: 5013 | D18: 0.02 | E18: Misma locación | F18: =MATCH(E18,{"Misma locación","0.15 - 5 km","5 - 10 km","10+ km"},0) -> 1 | G18: =MONTH(B18) -> 2 | H18: =COUNTIF($G$8:G18,G18) -> 4 | I18: 10 | J18: =INDEX(Simulador!$C$39:$F$39,F18) -> 12 | K18: =IF(I18="","",I18-J18) -> -2 | L18: =INDEX(Simulador!$C$51:$F$51,F18) -> 76047.405 | M18: =IF(H18>=Simulador!$C$19,INDEX(Simulador!$C$63:$F$63,F18),INDEX(Simulador!$C$62:$F$62,F18)) -> 55414.011 | N18: =INDEX(Simulador!$C$64:$F$64,F18) -> 65678.455 | O18: =IF(H18>=Simulador!$C$19,INDEX(Simulador!$C$65:$F$65,F18),INDEX(Simulador!$C$64:$F$64,F18)) -> 65678.455 | P18: =IF(H18>=Simulador!$C$19,INDEX(Simulador!$C$67:$F$67,F18),INDEX(Simulador!$C$66:$F$66,F18)) -> 55372.811 | Q18: =M18+(IF(I18="",J18+INDEX(Simulador!$C$40:$F$40,F18),I18)-J18-INDEX(Simulador!$C$40:$F$40,F18))*Simulador!$C$9-INDEX(Simulador!$C$69:$F$69,F18)+IF(Simulador!$N$7="Sí",MAX(0,IF(I18="",J18+INDEX(Simulador!$C$40:$F$40,F18),I18)-INDEX(Simulador!$C$41:$F$41,F18))*(INDEX(Simulador!$C$68:$F$68,F18)+Simulador!$N$8)/Simulador!$C$7,0) -> 52502.011 | R18: =N18+(IF(I18="",J18+INDEX(Simulador!$C$40:$F$40,F18),I18)-J18-INDEX(Simulador!$C$40:$F$40,F18))*Simulador!$C$9-INDEX(Simulador!$C$69:$F$69,F18)+IF(Simulador!$N$7="Sí",MAX(0,IF(I18="",J18+INDEX(Simulador!$C$40:$F$40,F18),I18)-INDEX(Simulador!$C$41:$F$41,F18))*(INDEX(Simulador!$C$68:$F$68,F18)+Simulador!$N$8)/Simulador!$C$7,0) -> 62766.455 | S18: =O18+(IF(I18="",J18+INDEX(Simulador!$C$40:$F$40,F18),I18)-J18-INDEX(Simulador!$C$40:$F$40,F18))*Simulador!$C$9-INDEX(Simulador!$C$69:$F$69,F18)+IF(Simulador!$N$7="Sí",MAX(0,IF(I18="",J18+INDEX(Simulador!$C$40:$F$40,F18),I18)-INDEX(Simulador!$C$41:$F$41,F18))*(INDEX(Simulador!$C$68:$F$68,F18)+Simulador!$N$8)/Simulador!$C$7,0) -> 62766.455 | T18: =P18+(IF(I18="",J18+INDEX(Simulador!$C$40:$F$40,F18),I18)-J18-INDEX(Simulador!$C$40:$F$40,F18))*Simulador!$C$9-INDEX(Simulador!$C$69:$F$69,F18)+IF(Simulador!$N$7="Sí",MAX(0,IF(I18="",J18+INDEX(Simulador!$C$40:$F$40,F18),I18)-INDEX(Simulador!$C$41:$F$41,F18))*(INDEX(Simulador!$C$68:$F$68,F18)+Simulador!$N$8)/Simulador!$C$7,0) -> 52460.811
B19: 45337 | C19: 5675 | D19: 3.4 | E19: 0.15 - 5 km | F19: =MATCH(E19,{"Misma locación","0.15 - 5 km","5 - 10 km","10+ km"},0) -> 2 | G19: =MONTH(B19) -> 2 | H19: =COUNTIF($G$8:G19,G19) -> 5 | I19: 12 | J19: =INDEX(Simulador!$C$39:$F$39,F19) -> 18 | K19: =IF(I19="","",I19-J19) -> -6 | L19: =INDEX(Simulador!$C$51:$F$51,F19) -> 99473.811 | M19: =IF(H19>=Simulador!$C$19,INDEX(Simulador!$C$63:$F$63,F19),INDEX(Simulador!$C$62:$F$62,F19)) -> 85898.023 | N19: =INDEX(Simulador!$C$64:$F$64,F19) -> 108447.11 | O19: =IF(H19>=Simulador!$C$19,INDEX(Simulador!$C$65:$F$65,F19),INDEX(Simulador!$C$64:$F$64,F19)) -> 108447.11 | P19: =IF(H19>=Simulador!$C$19,INDEX(Simulador!$C$67:$F$67,F19),INDEX(Simulador!$C$66:$F$66,F19)) -> 82343.946 | Q19: =M19+(IF(I19="",J19+INDEX(Simulador!$C$40:$F$40,F19),I19)-J19-INDEX(Simulador!$C$40:$F$40,F19))*Simulador!$C$9-INDEX(Simulador!$C$69:$F$69,F19)+IF(Simulador!$N$7="Sí",MAX(0,IF(I19="",J19+INDEX(Simulador!$C$40:$F$40,F19),I19)-INDEX(Simulador!$C$41:$F$41,F19))*(INDEX(Simulador!$C$68:$F$68,F19)+Simulador!$N$8)/Simulador!$C$7,0) -> 77162.023 | R19: =N19+(IF(I19="",J19+INDEX(Simulador!$C$40:$F$40,F19),I19)-J19-INDEX(Simulador!$C$40:$F$40,F19))*Simulador!$C$9-INDEX(Simulador!$C$69:$F$69,F19)+IF(Simulador!$N$7="Sí",MAX(0,IF(I19="",J19+INDEX(Simulador!$C$40:$F$40,F19),I19)-INDEX(Simulador!$C$41:$F$41,F19))*(INDEX(Simulador!$C$68:$F$68,F19)+Simulador!$N$8)/Simulador!$C$7,0) -> 99711.105 | S19: =O19+(IF(I19="",J19+INDEX(Simulador!$C$40:$F$40,F19),I19)-J19-INDEX(Simulador!$C$40:$F$40,F19))*Simulador!$C$9-INDEX(Simulador!$C$69:$F$69,F19)+IF(Simulador!$N$7="Sí",MAX(0,IF(I19="",J19+INDEX(Simulador!$C$40:$F$40,F19),I19)-INDEX(Simulador!$C$41:$F$41,F19))*(INDEX(Simulador!$C$68:$F$68,F19)+Simulador!$N$8)/Simulador!$C$7,0) -> 99711.105 | T19: =P19+(IF(I19="",J19+INDEX(Simulador!$C$40:$F$40,F19),I19)-J19-INDEX(Simulador!$C$40:$F$40,F19))*Simulador!$C$9-INDEX(Simulador!$C$69:$F$69,F19)+IF(Simulador!$N$7="Sí",MAX(0,IF(I19="",J19+INDEX(Simulador!$C$40:$F$40,F19),I19)-INDEX(Simulador!$C$41:$F$41,F19))*(INDEX(Simulador!$C$68:$F$68,F19)+Simulador!$N$8)/Simulador!$C$7,0) -> 73607.946
B20: 45342 | C20: 5141 | D20: 0.019202399 | E20: Misma locación | F20: =MATCH(E20,{"Misma locación","0.15 - 5 km","5 - 10 km","10+ km"},0) -> 1 | G20: =MONTH(B20) -> 2 | H20: =COUNTIF($G$8:G20,G20) -> 6 | I20: 14 | J20: =INDEX(Simulador!$C$39:$F$39,F20) -> 12 | K20: =IF(I20="","",I20-J20) -> 2 | L20: =INDEX(Simulador!$C$51:$F$51,F20) -> 76047.405 | M20: =IF(H20>=Simulador!$C$19,INDEX(Simulador!$C$63:$F$63,F20),INDEX(Simulador!$C$62:$F$62,F20)) -> 36443.006 | N20: =INDEX(Simulador!$C$64:$F$64,F20) -> 65678.455 | O20: =IF(H20>=Simulador!$C$19,INDEX(Simulador!$C$65:$F$65,F20),INDEX(Simulador!$C$64:$F$64,F20)) -> 41575.228 | P20: =IF(H20>=Simulador!$C$19,INDEX(Simulador!$C$67:$F$67,F20),INDEX(Simulador!$C$66:$F$66,F20)) -> 50763.892 | Q20: =M20+(IF(I20="",J20+INDEX(Simulador!$C$40:$F$40,F20),I20)-J20-INDEX(Simulador!$C$40:$F$40,F20))*Simulador!$C$9-INDEX(Simulador!$C$69:$F$69,F20)+IF(Simulador!$N$7="Sí",MAX(0,IF(I20="",J20+INDEX(Simulador!$C$40:$F$40,F20),I20)-INDEX(Simulador!$C$41:$F$41,F20))*(INDEX(Simulador!$C$68:$F$68,F20)+Simulador!$N$8)/Simulador!$C$7,0) -> 42069.33 | R20: =N20+(IF(I20="",J20+INDEX(Simulador!$C$40:$F$40,F20),I20)-J20-INDEX(Simulador!$C$40:$F$40,F20))*Simulador!$C$9-INDEX(Simulador!$C$69:$F$69,F20)+IF(Simulador!$N$7="Sí",MAX(0,IF(I20="",J20+INDEX(Simulador!$C$40:$F$40,F20),I20)-INDEX(Simulador!$C$41:$F$41,F20))*(INDEX(Simulador!$C$68:$F$68,F20)+Simulador!$N$8)/Simulador!$C$7,0) -> 71304.78 | S20: =O20+(IF(I20="",J20+INDEX(Simulador!$C$40:$F$40,F20),I20)-J20-INDEX(Simulador!$C$40:$F$40,F20))*Simulador!$C$9-INDEX(Simulador!$C$69:$F$69,F20)+IF(Simulador!$N$7="Sí",MAX(0,IF(I20="",J20+INDEX(Simulador!$C$40:$F$40,F20),I20)-INDEX(Simulador!$C$41:$F$41,F20))*(INDEX(Simulador!$C$68:$F$68,F20)+Simulador!$N$8)/Simulador!$C$7,0) -> 47201.552 | T20: =P20+(IF(I20="",J20+INDEX(Simulador!$C$40:$F$40,F20),I20)-J20-INDEX(Simulador!$C$40:$F$40,F20))*Simulador!$C$9-INDEX(Simulador!$C$69:$F$69,F20)+IF(Simulador!$N$7="Sí",MAX(0,IF(I20="",J20+INDEX(Simulador!$C$40:$F$40,F20),I20)-INDEX(Simulador!$C$41:$F$41,F20))*(INDEX(Simulador!$C$68:$F$68,F20)+Simulador!$N$8)/Simulador!$C$7,0) -> 56390.216
B21: 45346 | C21: 5032 | D21: 2.8 | E21: 0.15 - 5 km | F21: =MATCH(E21,{"Misma locación","0.15 - 5 km","5 - 10 km","10+ km"},0) -> 2 | G21: =MONTH(B21) -> 2 | H21: =COUNTIF($G$8:G21,G21) -> 7 | I21: 17 | J21: =INDEX(Simulador!$C$39:$F$39,F21) -> 18 | K21: =IF(I21="","",I21-J21) -> -1 | L21: =INDEX(Simulador!$C$51:$F$51,F21) -> 99473.811 | M21: =IF(H21>=Simulador!$C$19,INDEX(Simulador!$C$63:$F$63,F21),INDEX(Simulador!$C$62:$F$62,F21)) -> 56053.011 | N21: =INDEX(Simulador!$C$64:$F$64,F21) -> 108447.11 | O21: =IF(H21>=Simulador!$C$19,INDEX(Simulador!$C$65:$F$65,F21),INDEX(Simulador!$C$64:$F$64,F21)) -> 67327.553 | P21: =IF(H21>=Simulador!$C$19,INDEX(Simulador!$C$67:$F$67,F21),INDEX(Simulador!$C$66:$F$66,F21)) -> 59499.892 | Q21: =M21+(IF(I21="",J21+INDEX(Simulador!$C$40:$F$40,F21),I21)-J21-INDEX(Simulador!$C$40:$F$40,F21))*Simulador!$C$9-INDEX(Simulador!$C$69:$F$69,F21)+IF(Simulador!$N$7="Sí",MAX(0,IF(I21="",J21+INDEX(Simulador!$C$40:$F$40,F21),I21)-INDEX(Simulador!$C$41:$F$41,F21))*(INDEX(Simulador!$C$68:$F$68,F21)+Simulador!$N$8)/Simulador!$C$7,0) -> 54597.011 | R21: =N21+(IF(I21="",J21+INDEX(Simulador!$C$40:$F$40,F21),I21)-J21-INDEX(Simulador!$C$40:$F$40,F21))*Simulador!$C$9-INDEX(Simulador!$C$69:$F$69,F21)+IF(Simulador!$N$7="Sí",MAX(0,IF(I21="",J21+INDEX(Simulador!$C$40:$F$40,F21),I21)-INDEX(Simulador!$C$41:$F$41,F21))*(INDEX(Simulador!$C$68:$F$68,F21)+Simulador!$N$8)/Simulador!$C$7,0) -> 106991.11 | S21: =O21+(IF(I21="",J21+INDEX(Simulador!$C$40:$F$40,F21),I21)-J21-INDEX(Simulador!$C$40:$F$40,F21))*Simulador!$C$9-INDEX(Simulador!$C$69:$F$69,F21)+IF(Simulador!$N$7="Sí",MAX(0,IF(I21="",J21+INDEX(Simulador!$C$40:$F$40,F21),I21)-INDEX(Simulador!$C$41:$F$41,F21))*(INDEX(Simulador!$C$68:$F$68,F21)+Simulador!$N$8)/Simulador!$C$7,0) -> 65871.553 | T21: =P21+(IF(I21="",J21+INDEX(Simulador!$C$40:$F$40,F21),I21)-J21-INDEX(Simulador!$C$40:$F$40,F21))*Simulador!$C$9-INDEX(Simulador!$C$69:$F$69,F21)+IF(Simulador!$N$7="Sí",MAX(0,IF(I21="",J21+INDEX(Simulador!$C$40:$F$40,F21),I21)-INDEX(Simulador!$C$41:$F$41,F21))*(INDEX(Simulador!$C$68:$F$68,F21)+Simulador!$N$8)/Simulador!$C$7,0) -> 58043.892
B22: 45351 | C22: 5856 | D22: 2.8 | E22: 0.15 - 5 km | F22: =MATCH(E22,{"Misma locación","0.15 - 5 km","5 - 10 km","10+ km"},0) -> 2 | G22: =MONTH(B22) -> 2 | H22: =COUNTIF($G$8:G22,G22) -> 8 | I22: 22 | J22: =INDEX(Simulador!$C$39:$F$39,F22) -> 18 | K22: =IF(I22="","",I22-J22) -> 4 | L22: =INDEX(Simulador!$C$51:$F$51,F22) -> 99473.811 | M22: =IF(H22>=Simulador!$C$19,INDEX(Simulador!$C$63:$F$63,F22),INDEX(Simulador!$C$62:$F$62,F22)) -> 56053.011 | N22: =INDEX(Simulador!$C$64:$F$64,F22) -> 108447.11 | O22: =IF(H22>=Simulador!$C$19,INDEX(Simulador!$C$65:$F$65,F22),INDEX(Simulador!$C$64:$F$64,F22)) -> 67327.553 | P22: =IF(H22>=Simulador!$C$19,INDEX(Simulador!$C$67:$F$67,F22),INDEX(Simulador!$C$66:$F$66,F22)) -> 59499.892 | Q22: =M22+(IF(I22="",J22+INDEX(Simulador!$C$40:$F$40,F22),I22)-J22-INDEX(Simulador!$C$40:$F$40,F22))*Simulador!$C$9-INDEX(Simulador!$C$69:$F$69,F22)+IF(Simulador!$N$7="Sí",MAX(0,IF(I22="",J22+INDEX(Simulador!$C$40:$F$40,F22),I22)-INDEX(Simulador!$C$41:$F$41,F22))*(INDEX(Simulador!$C$68:$F$68,F22)+Simulador!$N$8)/Simulador!$C$7,0) -> 61877.011 | R22: =N22+(IF(I22="",J22+INDEX(Simulador!$C$40:$F$40,F22),I22)-J22-INDEX(Simulador!$C$40:$F$40,F22))*Simulador!$C$9-INDEX(Simulador!$C$69:$F$69,F22)+IF(Simulador!$N$7="Sí",MAX(0,IF(I22="",J22+INDEX(Simulador!$C$40:$F$40,F22),I22)-INDEX(Simulador!$C$41:$F$41,F22))*(INDEX(Simulador!$C$68:$F$68,F22)+Simulador!$N$8)/Simulador!$C$7,0) -> 114271.11 | S22: =O22+(IF(I22="",J22+INDEX(Simulador!$C$40:$F$40,F22),I22)-J22-INDEX(Simulador!$C$40:$F$40,F22))*Simulador!$C$9-INDEX(Simulador!$C$69:$F$69,F22)+IF(Simulador!$N$7="Sí",MAX(0,IF(I22="",J22+INDEX(Simulador!$C$40:$F$40,F22),I22)-INDEX(Simulador!$C$41:$F$41,F22))*(INDEX(Simulador!$C$68:$F$68,F22)+Simulador!$N$8)/Simulador!$C$7,0) -> 73151.553 | T22: =P22+(IF(I22="",J22+INDEX(Simulador!$C$40:$F$40,F22),I22)-J22-INDEX(Simulador!$C$40:$F$40,F22))*Simulador!$C$9-INDEX(Simulador!$C$69:$F$69,F22)+IF(Simulador!$N$7="Sí",MAX(0,IF(I22="",J22+INDEX(Simulador!$C$40:$F$40,F22),I22)-INDEX(Simulador!$C$41:$F$41,F22))*(INDEX(Simulador!$C$68:$F$68,F22)+Simulador!$N$8)/Simulador!$C$7,0) -> 65323.892
